{
 "cells": [
  {
   "cell_type": "code",
   "execution_count": 1,
   "metadata": {},
   "outputs": [
    {
     "ename": "ModuleNotFoundError",
     "evalue": "No module named 'tensorflow'",
     "output_type": "error",
     "traceback": [
      "\u001b[0;31m---------------------------------------------------------------------------\u001b[0m",
      "\u001b[0;31mModuleNotFoundError\u001b[0m                       Traceback (most recent call last)",
      "Cell \u001b[0;32mIn[1], line 1\u001b[0m\n\u001b[0;32m----> 1\u001b[0m \u001b[38;5;28;01mimport\u001b[39;00m \u001b[38;5;21;01mtensorflow\u001b[39;00m \u001b[38;5;28;01mas\u001b[39;00m \u001b[38;5;21;01mtf\u001b[39;00m\n\u001b[1;32m      2\u001b[0m \u001b[38;5;28;01mimport\u001b[39;00m \u001b[38;5;21;01mtorch\u001b[39;00m\n\u001b[1;32m      3\u001b[0m \u001b[38;5;28mprint\u001b[39m(tf\u001b[38;5;241m.\u001b[39m__version__ )\n",
      "\u001b[0;31mModuleNotFoundError\u001b[0m: No module named 'tensorflow'"
     ]
    }
   ],
   "source": [
    "import tensorflow as tf\n",
    "import torch\n",
    "print(tf.__version__ )\n",
    "print(\"TensorFlow CuDNN version:\", tf.sysconfig.get_build_info()[\"cudnn_version\"])\n",
    "print(\"PyTorch CuDNN version:\", torch.backends.cudnn.version())\n"
   ]
  },
  {
   "cell_type": "code",
   "execution_count": 2,
   "metadata": {},
   "outputs": [
    {
     "name": "stderr",
     "output_type": "stream",
     "text": [
      "/home/asanobm/miniforge3/envs/ai/lib/python3.11/site-packages/keras/src/layers/core/dense.py:87: UserWarning: Do not pass an `input_shape`/`input_dim` argument to a layer. When using Sequential models, prefer using an `Input(shape)` object as the first layer in the model instead.\n",
      "  super().__init__(activity_regularizer=activity_regularizer, **kwargs)\n",
      "I0000 00:00:1731796271.855207   46626 gpu_device.cc:2022] Created device /job:localhost/replica:0/task:0/device:GPU:0 with 22181 MB memory:  -> device: 0, name: NVIDIA GeForce RTX 4090, pci bus id: 0000:01:00.0, compute capability: 8.9\n",
      "I0000 00:00:1731796271.856286   46626 gpu_device.cc:2022] Created device /job:localhost/replica:0/task:0/device:GPU:1 with 22181 MB memory:  -> device: 1, name: NVIDIA GeForce RTX 4090, pci bus id: 0000:03:00.0, compute capability: 8.9\n"
     ]
    },
    {
     "name": "stdout",
     "output_type": "stream",
     "text": [
      "Epoch 1/5\n"
     ]
    },
    {
     "name": "stderr",
     "output_type": "stream",
     "text": [
      "WARNING: All log messages before absl::InitializeLog() is called are written to STDERR\n",
      "I0000 00:00:1731796272.537742   46783 service.cc:148] XLA service 0x7f5de80081e0 initialized for platform CUDA (this does not guarantee that XLA will be used). Devices:\n",
      "I0000 00:00:1731796272.537772   46783 service.cc:156]   StreamExecutor device (0): NVIDIA GeForce RTX 4090, Compute Capability 8.9\n",
      "I0000 00:00:1731796272.537775   46783 service.cc:156]   StreamExecutor device (1): NVIDIA GeForce RTX 4090, Compute Capability 8.9\n",
      "2024-11-16 22:31:12.551492: I tensorflow/compiler/mlir/tensorflow/utils/dump_mlir_util.cc:268] disabling MLIR crash reproducer, set env var `MLIR_CRASH_REPRODUCER_DIRECTORY` to enable.\n",
      "E0000 00:00:1731796272.596958   46783 cuda_dnn.cc:522] Loaded runtime CuDNN library: 9.1.0 but source was compiled with: 9.3.0.  CuDNN library needs to have matching major version and equal or higher minor version. If using a binary install, upgrade your CuDNN library.  If building from sources, make sure the library loaded at runtime is compatible with the version specified during compile configuration.\n",
      "E0000 00:00:1731796272.603561   46783 cuda_dnn.cc:522] Loaded runtime CuDNN library: 9.1.0 but source was compiled with: 9.3.0.  CuDNN library needs to have matching major version and equal or higher minor version. If using a binary install, upgrade your CuDNN library.  If building from sources, make sure the library loaded at runtime is compatible with the version specified during compile configuration.\n",
      "2024-11-16 22:31:12.605536: W tensorflow/core/framework/op_kernel.cc:1841] OP_REQUIRES failed at xla_ops.cc:577 : FAILED_PRECONDITION: DNN library initialization failed. Look at the errors above for more details.\n",
      "2024-11-16 22:31:12.605554: I tensorflow/core/framework/local_rendezvous.cc:405] Local rendezvous is aborting with status: FAILED_PRECONDITION: DNN library initialization failed. Look at the errors above for more details.\n",
      "\t [[{{node StatefulPartitionedCall}}]]\n"
     ]
    },
    {
     "ename": "FailedPreconditionError",
     "evalue": "Graph execution error:\n\nDetected at node StatefulPartitionedCall defined at (most recent call last):\n  File \"<frozen runpy>\", line 198, in _run_module_as_main\n\n  File \"<frozen runpy>\", line 88, in _run_code\n\n  File \"/home/asanobm/miniforge3/envs/ai/lib/python3.11/site-packages/ipykernel_launcher.py\", line 18, in <module>\n\n  File \"/home/asanobm/miniforge3/envs/ai/lib/python3.11/site-packages/traitlets/config/application.py\", line 1075, in launch_instance\n\n  File \"/home/asanobm/miniforge3/envs/ai/lib/python3.11/site-packages/ipykernel/kernelapp.py\", line 739, in start\n\n  File \"/home/asanobm/miniforge3/envs/ai/lib/python3.11/site-packages/tornado/platform/asyncio.py\", line 205, in start\n\n  File \"/home/asanobm/miniforge3/envs/ai/lib/python3.11/asyncio/base_events.py\", line 608, in run_forever\n\n  File \"/home/asanobm/miniforge3/envs/ai/lib/python3.11/asyncio/base_events.py\", line 1936, in _run_once\n\n  File \"/home/asanobm/miniforge3/envs/ai/lib/python3.11/asyncio/events.py\", line 84, in _run\n\n  File \"/home/asanobm/miniforge3/envs/ai/lib/python3.11/site-packages/ipykernel/kernelbase.py\", line 545, in dispatch_queue\n\n  File \"/home/asanobm/miniforge3/envs/ai/lib/python3.11/site-packages/ipykernel/kernelbase.py\", line 534, in process_one\n\n  File \"/home/asanobm/miniforge3/envs/ai/lib/python3.11/site-packages/ipykernel/kernelbase.py\", line 437, in dispatch_shell\n\n  File \"/home/asanobm/miniforge3/envs/ai/lib/python3.11/site-packages/ipykernel/ipkernel.py\", line 362, in execute_request\n\n  File \"/home/asanobm/miniforge3/envs/ai/lib/python3.11/site-packages/ipykernel/kernelbase.py\", line 778, in execute_request\n\n  File \"/home/asanobm/miniforge3/envs/ai/lib/python3.11/site-packages/ipykernel/ipkernel.py\", line 449, in do_execute\n\n  File \"/home/asanobm/miniforge3/envs/ai/lib/python3.11/site-packages/ipykernel/zmqshell.py\", line 549, in run_cell\n\n  File \"/home/asanobm/miniforge3/envs/ai/lib/python3.11/site-packages/IPython/core/interactiveshell.py\", line 3075, in run_cell\n\n  File \"/home/asanobm/miniforge3/envs/ai/lib/python3.11/site-packages/IPython/core/interactiveshell.py\", line 3130, in _run_cell\n\n  File \"/home/asanobm/miniforge3/envs/ai/lib/python3.11/site-packages/IPython/core/async_helpers.py\", line 128, in _pseudo_sync_runner\n\n  File \"/home/asanobm/miniforge3/envs/ai/lib/python3.11/site-packages/IPython/core/interactiveshell.py\", line 3334, in run_cell_async\n\n  File \"/home/asanobm/miniforge3/envs/ai/lib/python3.11/site-packages/IPython/core/interactiveshell.py\", line 3517, in run_ast_nodes\n\n  File \"/home/asanobm/miniforge3/envs/ai/lib/python3.11/site-packages/IPython/core/interactiveshell.py\", line 3577, in run_code\n\n  File \"/tmp/ipykernel_46626/3108625100.py\", line 19, in <module>\n\n  File \"/home/asanobm/miniforge3/envs/ai/lib/python3.11/site-packages/keras/src/utils/traceback_utils.py\", line 117, in error_handler\n\n  File \"/home/asanobm/miniforge3/envs/ai/lib/python3.11/site-packages/keras/src/backend/tensorflow/trainer.py\", line 320, in fit\n\n  File \"/home/asanobm/miniforge3/envs/ai/lib/python3.11/site-packages/keras/src/backend/tensorflow/trainer.py\", line 121, in one_step_on_iterator\n\nDNN library initialization failed. Look at the errors above for more details.\n\t [[{{node StatefulPartitionedCall}}]] [Op:__inference_one_step_on_iterator_968]",
     "output_type": "error",
     "traceback": [
      "\u001b[0;31m---------------------------------------------------------------------------\u001b[0m",
      "\u001b[0;31mFailedPreconditionError\u001b[0m                   Traceback (most recent call last)",
      "Cell \u001b[0;32mIn[2], line 19\u001b[0m\n\u001b[1;32m     16\u001b[0m y_train \u001b[38;5;241m=\u001b[39m np\u001b[38;5;241m.\u001b[39mrandom\u001b[38;5;241m.\u001b[39mrandint(\u001b[38;5;241m10\u001b[39m, size\u001b[38;5;241m=\u001b[39m(\u001b[38;5;241m1000\u001b[39m,))\n\u001b[1;32m     18\u001b[0m \u001b[38;5;66;03m# Train the model\u001b[39;00m\n\u001b[0;32m---> 19\u001b[0m \u001b[43mmodel\u001b[49m\u001b[38;5;241;43m.\u001b[39;49m\u001b[43mfit\u001b[49m\u001b[43m(\u001b[49m\u001b[43mx_train\u001b[49m\u001b[43m,\u001b[49m\u001b[43m \u001b[49m\u001b[43my_train\u001b[49m\u001b[43m,\u001b[49m\u001b[43m \u001b[49m\u001b[43mepochs\u001b[49m\u001b[38;5;241;43m=\u001b[39;49m\u001b[38;5;241;43m5\u001b[39;49m\u001b[43m)\u001b[49m\n",
      "File \u001b[0;32m~/miniforge3/envs/ai/lib/python3.11/site-packages/keras/src/utils/traceback_utils.py:122\u001b[0m, in \u001b[0;36mfilter_traceback.<locals>.error_handler\u001b[0;34m(*args, **kwargs)\u001b[0m\n\u001b[1;32m    119\u001b[0m     filtered_tb \u001b[38;5;241m=\u001b[39m _process_traceback_frames(e\u001b[38;5;241m.\u001b[39m__traceback__)\n\u001b[1;32m    120\u001b[0m     \u001b[38;5;66;03m# To get the full stack trace, call:\u001b[39;00m\n\u001b[1;32m    121\u001b[0m     \u001b[38;5;66;03m# `keras.config.disable_traceback_filtering()`\u001b[39;00m\n\u001b[0;32m--> 122\u001b[0m     \u001b[38;5;28;01mraise\u001b[39;00m e\u001b[38;5;241m.\u001b[39mwith_traceback(filtered_tb) \u001b[38;5;28;01mfrom\u001b[39;00m \u001b[38;5;28;01mNone\u001b[39;00m\n\u001b[1;32m    123\u001b[0m \u001b[38;5;28;01mfinally\u001b[39;00m:\n\u001b[1;32m    124\u001b[0m     \u001b[38;5;28;01mdel\u001b[39;00m filtered_tb\n",
      "File \u001b[0;32m~/miniforge3/envs/ai/lib/python3.11/site-packages/tensorflow/python/eager/execute.py:53\u001b[0m, in \u001b[0;36mquick_execute\u001b[0;34m(op_name, num_outputs, inputs, attrs, ctx, name)\u001b[0m\n\u001b[1;32m     51\u001b[0m \u001b[38;5;28;01mtry\u001b[39;00m:\n\u001b[1;32m     52\u001b[0m   ctx\u001b[38;5;241m.\u001b[39mensure_initialized()\n\u001b[0;32m---> 53\u001b[0m   tensors \u001b[38;5;241m=\u001b[39m pywrap_tfe\u001b[38;5;241m.\u001b[39mTFE_Py_Execute(ctx\u001b[38;5;241m.\u001b[39m_handle, device_name, op_name,\n\u001b[1;32m     54\u001b[0m                                       inputs, attrs, num_outputs)\n\u001b[1;32m     55\u001b[0m \u001b[38;5;28;01mexcept\u001b[39;00m core\u001b[38;5;241m.\u001b[39m_NotOkStatusException \u001b[38;5;28;01mas\u001b[39;00m e:\n\u001b[1;32m     56\u001b[0m   \u001b[38;5;28;01mif\u001b[39;00m name \u001b[38;5;129;01mis\u001b[39;00m \u001b[38;5;129;01mnot\u001b[39;00m \u001b[38;5;28;01mNone\u001b[39;00m:\n",
      "\u001b[0;31mFailedPreconditionError\u001b[0m: Graph execution error:\n\nDetected at node StatefulPartitionedCall defined at (most recent call last):\n  File \"<frozen runpy>\", line 198, in _run_module_as_main\n\n  File \"<frozen runpy>\", line 88, in _run_code\n\n  File \"/home/asanobm/miniforge3/envs/ai/lib/python3.11/site-packages/ipykernel_launcher.py\", line 18, in <module>\n\n  File \"/home/asanobm/miniforge3/envs/ai/lib/python3.11/site-packages/traitlets/config/application.py\", line 1075, in launch_instance\n\n  File \"/home/asanobm/miniforge3/envs/ai/lib/python3.11/site-packages/ipykernel/kernelapp.py\", line 739, in start\n\n  File \"/home/asanobm/miniforge3/envs/ai/lib/python3.11/site-packages/tornado/platform/asyncio.py\", line 205, in start\n\n  File \"/home/asanobm/miniforge3/envs/ai/lib/python3.11/asyncio/base_events.py\", line 608, in run_forever\n\n  File \"/home/asanobm/miniforge3/envs/ai/lib/python3.11/asyncio/base_events.py\", line 1936, in _run_once\n\n  File \"/home/asanobm/miniforge3/envs/ai/lib/python3.11/asyncio/events.py\", line 84, in _run\n\n  File \"/home/asanobm/miniforge3/envs/ai/lib/python3.11/site-packages/ipykernel/kernelbase.py\", line 545, in dispatch_queue\n\n  File \"/home/asanobm/miniforge3/envs/ai/lib/python3.11/site-packages/ipykernel/kernelbase.py\", line 534, in process_one\n\n  File \"/home/asanobm/miniforge3/envs/ai/lib/python3.11/site-packages/ipykernel/kernelbase.py\", line 437, in dispatch_shell\n\n  File \"/home/asanobm/miniforge3/envs/ai/lib/python3.11/site-packages/ipykernel/ipkernel.py\", line 362, in execute_request\n\n  File \"/home/asanobm/miniforge3/envs/ai/lib/python3.11/site-packages/ipykernel/kernelbase.py\", line 778, in execute_request\n\n  File \"/home/asanobm/miniforge3/envs/ai/lib/python3.11/site-packages/ipykernel/ipkernel.py\", line 449, in do_execute\n\n  File \"/home/asanobm/miniforge3/envs/ai/lib/python3.11/site-packages/ipykernel/zmqshell.py\", line 549, in run_cell\n\n  File \"/home/asanobm/miniforge3/envs/ai/lib/python3.11/site-packages/IPython/core/interactiveshell.py\", line 3075, in run_cell\n\n  File \"/home/asanobm/miniforge3/envs/ai/lib/python3.11/site-packages/IPython/core/interactiveshell.py\", line 3130, in _run_cell\n\n  File \"/home/asanobm/miniforge3/envs/ai/lib/python3.11/site-packages/IPython/core/async_helpers.py\", line 128, in _pseudo_sync_runner\n\n  File \"/home/asanobm/miniforge3/envs/ai/lib/python3.11/site-packages/IPython/core/interactiveshell.py\", line 3334, in run_cell_async\n\n  File \"/home/asanobm/miniforge3/envs/ai/lib/python3.11/site-packages/IPython/core/interactiveshell.py\", line 3517, in run_ast_nodes\n\n  File \"/home/asanobm/miniforge3/envs/ai/lib/python3.11/site-packages/IPython/core/interactiveshell.py\", line 3577, in run_code\n\n  File \"/tmp/ipykernel_46626/3108625100.py\", line 19, in <module>\n\n  File \"/home/asanobm/miniforge3/envs/ai/lib/python3.11/site-packages/keras/src/utils/traceback_utils.py\", line 117, in error_handler\n\n  File \"/home/asanobm/miniforge3/envs/ai/lib/python3.11/site-packages/keras/src/backend/tensorflow/trainer.py\", line 320, in fit\n\n  File \"/home/asanobm/miniforge3/envs/ai/lib/python3.11/site-packages/keras/src/backend/tensorflow/trainer.py\", line 121, in one_step_on_iterator\n\nDNN library initialization failed. Look at the errors above for more details.\n\t [[{{node StatefulPartitionedCall}}]] [Op:__inference_one_step_on_iterator_968]"
     ]
    }
   ],
   "source": [
    "import numpy as np\n",
    "\n",
    "# Create a simple neural network model using TensorFlow\n",
    "model = tf.keras.Sequential([\n",
    "  tf.keras.layers.Dense(128, activation='relu', input_shape=(784,)),\n",
    "  tf.keras.layers.Dense(10, activation='softmax')\n",
    "])\n",
    "\n",
    "# Compile the model\n",
    "model.compile(optimizer='adam',\n",
    "        loss='sparse_categorical_crossentropy',\n",
    "        metrics=['accuracy'])\n",
    "\n",
    "# Generate some dummy data for training\n",
    "x_train = np.random.random((1000, 784))\n",
    "y_train = np.random.randint(10, size=(1000,))\n",
    "\n",
    "# Train the model\n",
    "model.fit(x_train, y_train, epochs=5)"
   ]
  },
  {
   "cell_type": "code",
   "execution_count": null,
   "metadata": {},
   "outputs": [],
   "source": []
  },
  {
   "cell_type": "code",
   "execution_count": null,
   "metadata": {},
   "outputs": [],
   "source": []
  }
 ],
 "metadata": {
  "kernelspec": {
   "display_name": "ai",
   "language": "python",
   "name": "python3"
  },
  "language_info": {
   "codemirror_mode": {
    "name": "ipython",
    "version": 3
   },
   "file_extension": ".py",
   "mimetype": "text/x-python",
   "name": "python",
   "nbconvert_exporter": "python",
   "pygments_lexer": "ipython3",
   "version": "3.13.0"
  }
 },
 "nbformat": 4,
 "nbformat_minor": 2
}
